INFO     selenium.webdriver.remote.remote_connection:remote_connection.py:117 Could not connect to port 4444 on host 192.168.50.109
INFO     selenium.webdriver.remote.remote_connection:remote_connection.py:136 Could not get IP address for host: 192.168.50.109
WARNING  urllib3.connectionpool:connectionpool.py:745 Retrying (Retry(total=2, connect=None, read=None, redirect=None, status=None)) after connection broken by 'NewConnectionError('<urllib3.connection.HTTPConnection object at 0x0000019AE5DA8A48>: Failed to establish a new connection: [WinError 10060] A connection attempt failed because the connected party did not properly respond after a period of time, or established connection failed because connected host has failed to respond')': /wd/hub/session
WARNING  urllib3.connectionpool:connectionpool.py:745 Retrying (Retry(total=1, connect=None, read=None, redirect=None, status=None)) after connection broken by 'NewConnectionError('<urllib3.connection.HTTPConnection object at 0x0000019AE5DBE488>: Failed to establish a new connection: [WinError 10060] A connection attempt failed because the connected party did not properly respond after a period of time, or established connection failed because connected host has failed to respond')': /wd/hub/session
WARNING  urllib3.connectionpool:connectionpool.py:745 Retrying (Retry(total=0, connect=None, read=None, redirect=None, status=None)) after connection broken by 'NewConnectionError('<urllib3.connection.HTTPConnection object at 0x0000019AE5DBED08>: Failed to establish a new connection: [WinError 10060] A connection attempt failed because the connected party did not properly respond after a period of time, or established connection failed because connected host has failed to respond')': /wd/hub/session